Workbook

Sheet 目次
A1: システム名 | D1: 備蓄品管理システム | AA1: 章 | AC1: 節 | AE1: 項
A2: 章番号 | D2: ="第"&DBCS($AA$3)&"章 "&AB3 -> 第5章 ファイル設計 | AA2: 番 | AB2: 章分類 | AC2: 番 | AD2: 節分類 | AE2: 番 | AF2: 機能名
A3: 機能名 | AA3: 5 | AB3: ファイル設計 | AC3: 2 | AD3: ファイル詳細 | AE3: 2 | AF3: ビルデータ登録
A4: =IF($AA$3="","",DBCS($AA$3))&IF($AC$3="","",DBCS("."&$AC$3))&IF($AE$3="","",DBCS("."&$AE$3))&DBCS(" ")&$AF$3 -> 5.2.2 ビルデータ登録
AA6: 段
AA7: 番 | AB7: ファイル名
D8: =IF($AA8="","",IF($AA$3="","",DBCS($AA$3))&IF($AC$3="","",DBCS("."&$AC$3))&IF($AE$3="","",DBCS("."&$AE$3))&IF($AA8="","",DBCS("."&$AA8))&DBCS(" ")&$AB8) -> 5.2.2.1 ビルデータCSV | AA8: 1 | AB8: ビルデータCSV
D10: =IF($AA10="","",IF($AA$3="","",DBCS($AA$3))&IF($AC$3="","",DBCS("."&$AC$3))&IF($AE$3="","",DBCS("."&$AE$3))&IF($AA10="","",DBCS("."&$AA10))&DBCS(" ")&$AB10)
D12: =IF($AA12="","",IF($AA$3="","",DBCS($AA$3))&IF($AC$3="","",DBCS("."&$AC$3))&IF($AE$3="","",DBCS("."&$AE$3))&IF($AA12="","",DBCS("."&$AA12))&DBCS(" ")&$AB12)
D14: =IF($AA14="","",IF($AA$3="","",DBCS($AA$3))&IF($AC$3="","",DBCS("."&$AC$3))&IF($AE$3="","",DBCS("."&$AE$3))&IF($AA14="","",DBCS("."&$AA14))&DBCS(" ")&$AB14)
D16: =IF($AA16="","",IF($AA$3="","",DBCS($AA$3))&IF($AC$3="","",DBCS("."&$AC$3))&IF($AE$3="","",DBCS("."&$AE$3))&IF($AA16="","",DBCS("."&$AA16))&DBCS(" ")&$AB16)
D18: =IF($AA18="","",IF($AA$3="","",DBCS($AA$3))&IF($AC$3="","",DBCS("."&$AC$3))&IF($AE$3="","",DBCS("."&$AE$3))&IF($AA18="","",DBCS("."&$AA18))&DBCS(" ")&$AB18)
D20: =IF($AA20="","",IF($AA$3="","",DBCS($AA$3))&IF($AC$3="","",DBCS("."&$AC$3))&IF($AE$3="","",DBCS("."&$AE$3))&IF($AA20="","",DBCS("."&$AA20))&DBCS(" ")&$AB20)
D22: =IF($AA22="","",IF($AA$3="","",DBCS($AA$3))&IF($AC$3="","",DBCS("."&$AC$3))&IF($AE$3="","",DBCS("."&$AE$3))&IF($AA22="","",DBCS("."&$AA22))&DBCS(" ")&$AB22)
D24: =IF($AA24="","",IF($AA$3="","",DBCS($AA$3))&IF($AC$3="","",DBCS("."&$AC$3))&IF($AE$3="","",DBCS("."&$AE$3))&IF($AA24="","",DBCS("."&$AA24))&DBCS(" ")&$AB24)
D26: =IF($AA26="","",IF($AA$3="","",DBCS($AA$3))&IF($AC$3="","",DBCS("."&$AC$3))&IF($AE$3="","",DBCS("."&$AE$3))&IF($AA26="","",DBCS("."&$AA26))&DBCS(" ")&$AB26)
D28: =IF($AA28="","",IF($AA$3="","",DBCS($AA$3))&IF($AC$3="","",DBCS("."&$AC$3))&IF($AE$3="","",DBCS("."&$AE$3))&IF($AA28="","",DBCS("."&$AA28))&DBCS(" ")&$AB28)
D30: =IF($AA30="","",IF($AA$3="","",DBCS($AA$3))&IF($AC$3="","",DBCS("."&$AC$3))&IF($AE$3="","",DBCS("."&$AE$3))&IF($AA30="","",DBCS("."&$AA30))&DBCS(" ")&$AB30)
D32: =IF($AA32="","",IF($AA$3="","",DBCS($AA$3))&IF($AC$3="","",DBCS("."&$AC$3))&IF($AE$3="","",DBCS("."&$AE$3))&IF($AA32="","",DBCS("."&$AA32))&DBCS(" ")&$AB32)
D34: =IF($AA34="","",IF($AA$3="","",DBCS($AA$3))&IF($AC$3="","",DBCS("."&$AC$3))&IF($AE$3="","",DBCS("."&$AE$3))&IF($AA34="","",DBCS("."&$AA34))&DBCS(" ")&$AB34)

Sheet ビルデータCSV_1(ヘッダ)
A1: システム名 | I1: 章番号 | P1: 機能名 | Z1: Ｖｅｒ. | AC1: 1.0
A2: =目次!D1 -> 備蓄品管理システム | I2: =目次!D2 -> 第5章 ファイル設計 | P2: =目次!A4 -> 5.2.2 ビルデータ登録 | Z2: 作成日 | AC2: 42398 | AF2: 作成者 | AI2: 協和エクシオ
Z3: 更新日 | AF3: 更新者
A4: ファイル名 | E4: =目次!D8 -> 5.2.2.1 ビルデータCSV | P4: 出力形態 | T4: CSV
B6: 【1】項目定義 1/5
B8: № | C8: 項目名 | H8: 項目説明 | Q8: フォーマット | X8: 必須 | Z8: 属性 | AC8: 桁数 | AE8: 備考
C9: 【ヘッダーエリア①】 | Q9: ファイルの１行目に必ず設定する
B10: 1 | C10: 処理ユーザＩＤ名称 | H10: ヘッダエリア①の項目名称 | Q10: "処理ユーザＩＤ" | X10: － | Z10: － | AC10: －
B12: =B10+1 -> 2 | C12: 処理ユーザＩＤ | H12: CSV出力を処理したユーザのユーザＩＤ | Q12: － | X12: － | Z12: 半角英数記号 | AC12: 20
B14: =B12+1 -> 3 | C14: 出力日時名称 | H14: データエリアの項目名称 | Q14: "出力日時" | X14: － | Z14: － | AC14: －
B16: =B14+1 -> 4 | C16: 出力日時 | H16: CSV出力を処理した日時 | Q16: yyyy/mm/dd hh:mm | X16: - | Z16: 年月日時分 | AC16: 16
C18: 【ヘッダーエリア②】 | Q18: ファイルの２行目に必ず設定する
B19: 1 | C19: ="項目"&DBCS(B19)&"名称" -> 項目1名称 | H19: データエリアの項目名称 | Q19: "グループ名" | X19: ○ | Z19: － | AC19: －
B21: 2 | C21: ="項目"&DBCS(B21)&"名称" -> 項目2名称 | H21: データエリアの項目名称 | Q21: "会社名" | X21: ○ | Z21: － | AC21: －
B23: =B21+1 -> 3 | C23: ="項目"&DBCS(B23)&"名称" -> 項目3名称 | H23: データエリアの項目名称 | Q23: "組織名" | X23: ○ | Z23: － | AC23: －
B25: =B23+1 -> 4 | C25: ="項目"&DBCS(B25)&"名称" -> 項目4名称 | H25: データエリアの項目名称 | Q25: "ビルコード" | X25: ○ | Z25: － | AC25: －
B27: =B25+1 -> 5 | C27: ="項目"&DBCS(B27)&"名称" -> 項目5名称 | H27: データエリアの項目名称 | Q27: "ビル名" | X27: ○ | Z27: － | AC27: －
B29: =B27+1 -> 6 | C29: ="項目"&DBCS(B29)&"名称" -> 項目6名称 | H29: データエリアの項目名称 | Q29: "郵便番号" | X29: ○ | Z29: － | AC29: －
B31: =B29+1 -> 7 | C31: ="項目"&DBCS(B31)&"名称" -> 項目7名称 | H31: データエリアの項目名称 | Q31: "住所" | X31: ○ | Z31: － | AC31: －
B33: =B31+1 -> 8 | C33: ="項目"&DBCS(B33)&"名称" -> 項目8名称 | H33: データエリアの項目名称 | Q33: "規模" | X33: ○ | Z33: － | AC33: －
B35: =B33+1 -> 9 | C35: ="項目"&DBCS(B35)&"名称" -> 項目9名称 | H35: データエリアの項目名称 | Q35: "住所更新フラグ" | X35: ○ | Z35: － | AC35: －
B37: =B35+1 -> 10 | C37: ="項目"&DBCS(B37)&"名称" -> 項目10名称 | H37: データエリアの項目名称 | Q37: "電話番号" | X37: ○ | Z37: － | AC37: －
B39: =B37+1 -> 11 | C39: ="項目"&DBCS(B39)&"名称" -> 項目11名称 | H39: データエリアの項目名称 | Q39: "ＦＡＸ番号" | X39: ○ | Z39: － | AC39: －
B44: 【1】項目定義 2/5
B46: № | C46: 項目名 | H46: 項目説明 | Q46: フォーマット | X46: 必須 | Z46: 属性 | AC46: 桁数 | AE46: 備考
B47: =B39+1 -> 12 | C47: ="項目"&DBCS(B47)&"名称" -> 項目12名称 | H47: データエリアの項目名称 | Q47: "所有者" | X47: ○ | Z47: － | AC47: －
B49: =B47+1 -> 13 | C49: ="項目"&DBCS(B49)&"名称" -> 項目13名称 | H49: データエリアの項目名称 | Q49: "代表者" | X49: ○ | Z49: － | AC49: －
B51: =B49+1 -> 14 | C51: ="項目"&DBCS(B51)&"名称" -> 項目14名称 | H51: データエリアの項目名称 | Q51: "社員数" | X51: ○ | Z51: － | AC51: －
B53: =B51+1 -> 15 | C53: ="項目"&DBCS(B53)&"名称" -> 項目15名称 | H53: データエリアの項目名称 | Q53: "ＮＴＴ在籍出向者数" | X53: ○ | Z53: － | AC53: －
B55: =B53+1 -> 16 | C55: ="項目"&DBCS(B55)&"名称" -> 項目16名称 | H55: データエリアの項目名称 | Q55: "他社出向者数" | X55: ○ | Z55: － | AC55: －
B57: =B55+1 -> 17 | C57: ="項目"&DBCS(B57)&"名称" -> 項目17名称 | H57: データエリアの項目名称 | Q57: "ＮＴＴ転籍者数" | X57: ○ | Z57: － | AC57: －
B59: =B57+1 -> 18 | C59: ="項目"&DBCS(B59)&"名称" -> 項目18名称 | H59: データエリアの項目名称 | Q59: "自社採用社員数" | X59: ○ | Z59: － | AC59: －
B61: =B59+1 -> 19 | C61: ="項目"&DBCS(B61)&"名称" -> 項目19名称 | H61: データエリアの項目名称 | Q61: "年俸契約社員数" | X61: ○ | Z61: － | AC61: －
B63: =B61+1 -> 20 | C63: ="項目"&DBCS(B63)&"名称" -> 項目20名称 | H63: データエリアの項目名称 | Q63: "ＮＴＴＯＢ社員数" | X63: ○ | Z63: － | AC63: －
B65: =B63+1 -> 21 | C65: ="項目"&DBCS(B65)&"名称" -> 項目21名称 | H65: データエリアの項目名称 | Q65: "他社ＯＢ社員数" | X65: ○ | Z65: － | AC65: －
B67: =B65+1 -> 22 | C67: ="項目"&DBCS(B67)&"名称" -> 項目22名称 | H67: データエリアの項目名称 | Q67: "退職・再雇用社員数" | X67: ○ | Z67: － | AC67: －
B69: =B67+1 -> 23 | C69: ="項目"&DBCS(B69)&"名称" -> 項目23名称 | H69: データエリアの項目名称 | Q69: "役員" | X69: ○ | Z69: － | AC69: －
B71: =B69+1 -> 24 | C71: ="項目"&DBCS(B71)&"名称" -> 項目24名称 | H71: データエリアの項目名称 | Q71: "臨時雇（パート）数" | X71: ○ | Z71: － | AC71: －
... B77: =B75+1 -> 27 | C77: ="項目"&DBCS(B77)&"名称" -> 項目27名称 | H77: データエリアの項目名称 | Q77: "人材派遣数" | X77: ○ | Z77: － | AC77: －
B82: 【1】項目定義 3/5
...

Sheet ビルデータCSV_1(データ)
A1: システム名 | I1: 章番号 | P1: 機能名 | Z1: Ｖｅｒ. | AC1: 1.0
A2: =目次!D1 -> 備蓄品管理システム | I2: =目次!D2 -> 第5章 ファイル設計 | P2: =目次!A4 -> 5.2.2 ビルデータ登録 | Z2: 作成日 | AC2: 42398 | AF2: 作成者 | AI2: 協和エクシオ
Z3: 更新日 | AF3: 更新者
A4: ファイル名 | E4: =目次!D8 -> 5.2.2.1 ビルデータCSV | P4: 出力形態 | T4: CSV
B6: 【1】項目定義 4/5
B8: № | C8: 項目名 | H8: 項目説明 | Q8: フォーマット | X8: 必須 | Z8: 属性 | AC8: 桁数 | AE8: 備考
C9: 【データエリア】 | Q9: データ数により動的に行を追加
B10: 1 | C10: グループ名 | H10: グループ名 | Q10: － | X10: ○ | Z10: 全半角 | AC10: 最大50
B12: 2 | C12: 会社名 | H12: 会社名 | Q12: － | X12: ○ | Z12: 全半角 | AC12: 最大50
B14: =B12+1 -> 3 | C14: 組織名 | H14: 組織名 | Q14: － | X14: ○ | Z14: 全半角 | AC14: 最大50
B16: =B14+1 -> 4 | C16: ビルコード | H16: ビルコード | Q16: 0000 | X16: ○ | Z16: 数字 | AC16: 4
B18: =B16+1 -> 5 | C18: ビル名 | H18: ビルの名称 | Q18: － | X18: ○ | Z18: 全半角 | AC18: 最大50
B20: =B18+1 -> 6 | C20: 郵便番号 | H20: ビルまたは入居会社の郵便番号 | Q20: － | X20: － | Z20: 半角英数記号 | AC20: 最大8 | AE20: 半角ハイフン付きも許容
B22: =B20+1 -> 7 | C22: 住所 | H22: ビルまたは入居会社の住所 | Q22: － | X22: ○ | Z22: 全半角 | AC22: 最大200
B24: =B22+1 -> 8 | C24: 規模 | H24: 拠点規模 | Q24: － | X24: － | Z24: 数字 | AC24: 4
B26: =B24+1 -> 9 | C26: 住所更新フラグ | H26: 住所を地図用の緯度経度に変換するかシステムで識別するフラグ値 | Q26: "" ：更新しない "0"：更新しない "1"：更新する ※NO35,36のデータが入っている場合は、NO35,36の緯度経度を使用し更新する。 | X26: － | Z26: 数字 | AC26: 1 | AE26: ビルデータCSV出力時は全件"0"でファイルに出力
B29: =B26+1 -> 10 | C29: 電話番号 | H29: ビルまたは入居会社の電話番号 | Q29: － | X29: － | Z29: 半角英数記号 | AC29: 最大13 | AE29: 半角ハイフン付きも許容
B31: =B29+1 -> 11 | C31: ＦＡＸ番号 | H31: ビルまたは入居会社のＦＡＸ番号 | Q31: － | X31: － | Z31: 半角英数記号 | AC31: 最大13 | AE31: 半角ハイフン付きも許容
B33: =B31+1 -> 12 | C33: 所有者 | H33: ビルまたは入居会社の所有者 | Q33: － | X33: － | Z33: 全半角 | AC33: 最大15
B35: =B33+1 -> 13 | C35: 代表者 | H35: ビルまたは入居会社の代表者 | Q35: － | X35: － | Z35: 全半角 | AC35: 最大15
B37: =B35+1 -> 14 | C37: 正社員数 （東日本社員） | H37: 入居会社の正社員数 | Q37: － | X37: ○ | Z37: 数字 | AC37: 最大5
B39: =B37+1 -> 15 | C39: 正社員数 （ＮＴＴ在籍出向者） | H39: 入居会社の正社員数 | Q39: － | X39: ○ | Z39: 数字 | AC39: 最大5
B41: =B39+1 -> 16 | C41: 正社員数 （他社出向者） | H41: 入居会社の正社員数 | Q41: － | X41: ○ | Z41: 数字 | AC41: 最大5
B46: 【1】項目定義 5/5
B48: № | C48: 項目名 | H48: 項目説明 | Q48: フォーマット | X48: 必須 | Z48: 属性 | AC48: 桁数 | AE48: 備考
B49: =B41+1 -> 17 | C49: 正社員数 （ＮＴＴ転籍者） | H49: 入居会社の正社員数 | Q49: － | X49: ○ | Z49: 数字 | AC49: 最大5
B51: =B49+1 -> 18 | C51: 正社員数 （自社採用社員） | H51: 入居会社の正社員数 | Q51: － | X51: ○ | Z51: 数字 | AC51: 最大5
B53: =B51+1 -> 19 | C53: 正社員数 （年俸契約社員） | H53: 入居会社の正社員数 | Q53: － | X53: ○ | Z53: 数字 | AC53: 最大5
B55: =B53+1 -> 20 | C55: 正社員数 （ＮＴＴＯＢ社員） | H55: 入居会社の正社員数 | Q55: － | X55: ○ | Z55: 数字 | AC55: 最大5
B57: =B55+1 -> 21 | C57: 正社員数 （他社ＯＢ社員） | H57: 入居会社の正社員数 | Q57: － | X57: ○ | Z57: 数字 | AC57: 最大5
B59: =B57+1 -> 22 | C59: 正社員数 （退職・再雇用社員） | H59: 入居会社の正社員数 | Q59: － | X59: ○ | Z59: 数字 | AC59: 最大5
B61: =B59+1 -> 23 | C61: 正社員数 （役員） | H61: 入居会社の正社員数 | Q61: － | X61: ○ | Z61: 数字 | AC61: 最大5
B63: =B61+1 -> 24 | C63: 非正規社員数 （臨時雇（パート）） | H63: 入居会社の正社員数 | Q63: － | X63: ○ | Z63: 数字 | AC63: 最大5
B65: =B63+1 -> 25 | C65: 非正規社員数 （嘱託） | H65: 入居会社の非正社員数 | Q65: － | X65: ○ | Z65: 数字 | AC65: 最大5
B67: =B65+1 -> 26 | C67: 非正規社員数 （その他の契約社員） | H67: 入居会社の非正社員数 | Q67: － | X67: ○ | Z67: 数字 | AC67: 最大5
B69: =B67+1 -> 27 | C69: 非正規社員数 （人材派遣） | H69: 入居会社の非正社員数 | Q69: － | X69: ○ | Z69: 数字 | AC69: 最大5
B71: =B69+1 -> 28 | C71: 非正規社員数 （60歳超え契約社員） | H71: 入居会社の非正社員数 | Q71: － | X71: ○ | Z71: 数字 | AC71: 最大5
B73: =B71+1 -> 29 | C73: 登録日時 | H73: ビルデータの登録を処理した日時 | Q73: yyyy/mm/dd hh:mm | X73: - | Z73: 年月日時分 | AC73: 16 | AE73: 当項目の値はビルデータCSV登録処理では無視する
B75: =B73+1 -> 30 | C75: 最終更新日時 | H75: ビルデータを最後に更新処理した日時 | Q75: yyyy/mm/dd hh:mm | X75: - | Z75: 年月日時分 | AC75: 16 | AE75: 当項目の値はビルデータCSV登録処理では無視する
B77: =B75+1 -> 31 | C77: フリー項目１（※１） | Q77: － | X77: － | Z77: 全半角 | AC77: 最大150
...

Sheet ビルデータCSV_2
A1: システム名 | I1: 章番号 | P1: 機能名 | Z1: Ｖｅｒ. | AC1: 1.0
A2: =[1]目次!D1 -> 備蓄品管理システム | I2: =[1]目次!D2 -> 第５章 ファイル設計 | P2: =[1]目次!A4 -> ５．２．２ ビルデータ登録 | Z2: 作成日 | AC2: 42398 | AF2: 作成者 | AI2: 協和エクシオ
Z3: 更新日 | AF3: 更新者
A4: ファイル名 | E4: =[1]目次!D8 -> ５．２．２．１ ビルデータCSV | P4: 出力形態 | T4: CSV
B6: 【2】ソート条件 1/1
B8: ①規定での出力ソート順序
B9: ソート順序 | G9: 項目名 | P9: 昇順/降順 | W9: 備考
B10: 1 | G10: グループコード | P10: 昇順
B11: 2 | G11: 会社ID | P11: 昇順
B12: 3 | G12: 組織 | P12: 昇順
B13: 4 | G13: ビルコード | P13: 昇順
B15: ②画面指定での出力ソート順序
B16: ソート順序 | G16: 項目名 | P16: 昇順/降順 | W16: 備考
B17: 1 | G17: ビルコード／正社員数／非正社員数／ 最終更新日時 | P17: 昇順/降順 | W17: ビルデータ一覧のソート順に準拠する
B19: 2 | G19: グループコード | P19: 昇順
B20: 3 | G20: 会社ID | P20: 昇順
B21: 4 | G21: 組織 | P21: 昇順
B24: 【3】出力元機能 1/1
B26: № | C26: 機能名 | K26: 画面名称
B27: 1 | C27: ビルデータ登録 | K27: ビルデータ一覧
