Workbook

Sheet 目次
A1: システム名 | D1: 備蓄品管理システム | T1: Ｖｅｒ. | V1: 1.0 | AA1: 章 | AC1: 節 | AE1: 項
A2: 章番号 | D2: ="第"&DBCS($AA$3)&"章 "&AB3 -> 第２章 画面設計 | T2: 作成日 | V2: 2016/1/26 | AA2: 番 | AB2: 章分類 | AC2: 番 | AD2: 節分類 | AE2: 番 | AF2: 機能名
A3: 機能名 | T3: 作成者 | V3: 協和エクシオ | AA3: 2 | AB3: 画面設計 | AC3: 3 | AD3: 画面詳細 | AE3: 7 | AF3: ビルデータ登録
A4: =IF($AA$3="","",DBCS($AA$3))&IF($AC$3="","",DBCS("."&$AC$3))&IF($AE$3="","",DBCS("."&$AE$3))&DBCS(" ")&$AF$3 -> ２．３．７ ビルデータ登録 | T4: 更新日
T5: 更新者
AA6: 段
AA7: 番 | AB7: 処理名
D8: =IF($AA8="","",IF($AA$3="","",DBCS($AA$3))&IF($AC$3="","",DBCS("."&$AC$3))&IF($AE$3="","",DBCS("."&$AE$3))&IF($AA8="","",DBCS("."&$AA8))&DBCS(" ")&$AB8) -> ２．３．７．１ ビルデータ一覧 | AA8: 1 | AB8: ビルデータ一覧
D10: =IF($AA10="","",IF($AA$3="","",DBCS($AA$3))&IF($AC$3="","",DBCS("."&$AC$3))&IF($AE$3="","",DBCS("."&$AE$3))&IF($AA10="","",DBCS("."&$AA10))&DBCS(" ")&$AB10) -> ２．３．７．２ ビルデータ登録 | AA10: 2 | AB10: ビルデータ登録
D12: =IF($AA12="","",IF($AA$3="","",DBCS($AA$3))&IF($AC$3="","",DBCS("."&$AC$3))&IF($AE$3="","",DBCS("."&$AE$3))&IF($AA12="","",DBCS("."&$AA12))&DBCS(" ")&$AB12) -> ２．３．７．３ ビルデータ詳細 | AA12: 3 | AB12: ビルデータ詳細
D14: =IF($AA14="","",IF($AA$3="","",DBCS($AA$3))&IF($AC$3="","",DBCS("."&$AC$3))&IF($AE$3="","",DBCS("."&$AE$3))&IF($AA14="","",DBCS("."&$AA14))&DBCS(" ")&$AB14) -> ２．３．７．４ ビルデータ修正 | AA14: 4 | AB14: ビルデータ修正
D16: =IF($AA16="","",IF($AA$3="","",DBCS($AA$3))&IF($AC$3="","",DBCS("."&$AC$3))&IF($AE$3="","",DBCS("."&$AE$3))&IF($AA16="","",DBCS("."&$AA16))&DBCS(" ")&$AB16) -> ２．３．７．５ ビルデータCSV登録 | AA16: 5 | AB16: ビルデータCSV登録
D18: =IF($AA18="","",IF($AA$3="","",DBCS($AA$3))&IF($AC$3="","",DBCS("."&$AC$3))&IF($AE$3="","",DBCS("."&$AE$3))&IF($AA18="","",DBCS("."&$AA18))&DBCS(" ")&$AB18) -> ２．３．７．６ 別紙＿権限 | AA18: 6 | AB18: 別紙＿権限
D20: =IF($AA20="","",IF($AA$3="","",DBCS($AA$3))&IF($AC$3="","",DBCS("."&$AC$3))&IF($AE$3="","",DBCS("."&$AE$3))&IF($AA20="","",DBCS("."&$AA20))&DBCS(" ")&$AB20)
D22: =IF($AA22="","",IF($AA$3="","",DBCS($AA$3))&IF($AC$3="","",DBCS("."&$AC$3))&IF($AE$3="","",DBCS("."&$AE$3))&IF($AA22="","",DBCS("."&$AA22))&DBCS(" ")&$AB22)
D24: =IF($AA24="","",IF($AA$3="","",DBCS($AA$3))&IF($AC$3="","",DBCS("."&$AC$3))&IF($AE$3="","",DBCS("."&$AE$3))&IF($AA24="","",DBCS("."&$AA24))&DBCS(" ")&$AB24)
D26: =IF($AA26="","",IF($AA$3="","",DBCS($AA$3))&IF($AC$3="","",DBCS("."&$AC$3))&IF($AE$3="","",DBCS("."&$AE$3))&IF($AA26="","",DBCS("."&$AA26))&DBCS(" ")&$AB26)
D28: =IF($AA28="","",IF($AA$3="","",DBCS($AA$3))&IF($AC$3="","",DBCS("."&$AC$3))&IF($AE$3="","",DBCS("."&$AE$3))&IF($AA28="","",DBCS("."&$AA28))&DBCS(" ")&$AB28)
D30: =IF($AA30="","",IF($AA$3="","",DBCS($AA$3))&IF($AC$3="","",DBCS("."&$AC$3))&IF($AE$3="","",DBCS("."&$AE$3))&IF($AA30="","",DBCS("."&$AA30))&DBCS(" ")&$AB30)
D32: =IF($AA32="","",IF($AA$3="","",DBCS($AA$3))&IF($AC$3="","",DBCS("."&$AC$3))&IF($AE$3="","",DBCS("."&$AE$3))&IF($AA32="","",DBCS("."&$AA32))&DBCS(" ")&$AB32)
D34: =IF($AA34="","",IF($AA$3="","",DBCS($AA$3))&IF($AC$3="","",DBCS("."&$AC$3))&IF($AE$3="","",DBCS("."&$AE$3))&IF($AA34="","",DBCS("."&$AA34))&DBCS(" ")&$AB34)

Sheet ビルデータ一覧画面_1
A1: システム名 | D1: =目次!D1 -> 備蓄品管理システム | T1: Ｖｅｒ. | V1: 1.0
A2: =目次!A2 -> 章番号 | D2: =目次!D2 -> 第２章 画面設計 | T2: 作成日 | V2: 42398
A3: =目次!A3 -> 機能名 | T3: 作成者 | V3: 協和エクシオ
A4: =目次!A4 -> ２．３．７ ビルデータ登録 | T4: 更新日
T5: 更新者
A6: 画面名 | D6: =目次!D8 -> ２．３．７．１ ビルデータ一覧 | O6: ＩＤ
B8: 【1】画面定義
B33: № | C33: 説 明
B34: 1 | C34: 【検索エリア】
C35: ・ 検索条件に該当するビルデータ情報のみを抽出して、一覧を絞り込み表示する。
C36: ・ 閉じるボタンで検索エリアを閉じる。
C37: [検索ボタン]
C38: ボタン押下で、入力条件に該当するビルデータ情報を検索し、結果を一覧エリアに表示する。
C39: [クリアボタン]
C40: ボタン押下で、検索エリア内項目を初期表示時の状態に戻す。
C41: [閉じるボタン]
C42: ボタン押下で、検索エリアの表示/非表示を行う。
B44: 2 | C44: 【ビルデータ一覧エリア】
C45: ・ ビルデータ情報を一覧表示する。
C46: ・ ビルデータ一覧は、以下のソート項目で並び替えした後に初期表示する。
E47: ソート項目 | K47: ソート順
E48: グループコード | K48: 昇順
E49: 会社コード | K49: 昇順
E50: 組織コード | K50: 昇順
E51: ビルコード | K51: 昇順
C53: [ビル登録画面へボタン]
C54: ボタン押下で、ビルデータ登録画面へ遷移する。
C55: [ビルCSV登録画面へボタン]
C56: ボタン押下で、ビルデータCSV登録画面へ遷移する。
C57: [ビルCSV出力ボタン]
C58: ボタン押下で、一覧に表示中のビルデータ情報をCSVに出力する。
C59: [一覧行選択]
C60: 一覧の行にカーソルを合わせ、行をクリックすると、
C61: 指定された記録に該当するビルデータ詳細画面へ遷移する。
B69: (2/2)
B70: № | C70: 説 明
B71: 3 | C71: 【ユーザ権限によるデータの利用範囲】
C72: ・ ログインユーザの権限（ユーザレベル）により、データ利用の範囲を制限する。
D73: 「２．３．７．６ 別紙＿権限」を参照

Sheet ビルデータ一覧画面_2
A1: システム名 | I1: 章番号 | P1: 機能名 | Z1: Ｖｅｒ. | AC1: 1.0
A2: =目次!D1 -> 備蓄品管理システム | I2: =目次!D2 -> 第２章 画面設計 | P2: =目次!A4 -> ２．３．７ ビルデータ登録 | Z2: 作成日 | AC2: 42398 | AF2: 作成者 | AI2: 協和エクシオ
Z3: 更新日 | AF3: 更新者
A4: 画面名 | I4: =目次!D8 -> ２．３．７．１ ビルデータ一覧 | Z4: 画面ＩＤ
B6: 【2】画面項目定義
B8: № | C8: 項目名 | H8: ｺﾝﾎﾟｰﾈﾝﾄ種別 | N8: 必須 入力 | P8: 項目説明
H9: 出力形式 | K9: 入力形式 | P9: 属性 | T9: 最大文字数 | X9: 初期表示
C10: 【ヘッダーバー】 | N10: ２．３．１ 共通機能 ２．３．１．１ 共通処理参照
B11: 1 | C11: ヘッダー文言① | H11: テキストエリア | N11: － | P11: ログイン中のユーザ名を表示する。
H12: テキスト | K12: － | P12: － | T12: － | X12: ”ユーザ名：” + ログイン中のユーザ名
B13: 2 | C13: ヘッダー文言② | H13: テキストエリア | N13: － | P13: ログイン中のユーザ名が所属する組織名を表示する。
H14: テキスト | K14: － | P14: － | T14: － | X14: ”組織名：” + ログイン中のユーザの組織名
B15: 3 | C15: ヘッダー文言③ | H15: テキストエリア | N15: － | P15: 検索結果件数を表示する。
H16: テキスト | K16: － | P16: － | T16: － | X16: ”検索結果：” + 一覧表示中のビルデータ情報件数＋”件”
B17: 4 | C17: 前に戻る | H17: ボタン | N17: － | P17: 前画面に戻る。
H18: － | K18: － | P18: － | T18: － | X18: －
C19: 【メッセージエリア】
B20: 5 | C20: メッセージエリア | H20: テキストエリア | N20: － | P20: エラーがあった場合は、エラーの内容を表示（※１）する。
H21: テキスト | K21: － | P21: － | T21: － | X21: 非表示
C22: 【検索エリア】
B23: 6 | C23: ビルコード | H23: テキスト | N23: － | P23: 検索対象とするビルコードを入力する。
H24: － | K24: 入力 | P24: 数字 | T24: 4 | X24: 空欄
B25: 7 | C25: ビル名 | H25: プルダウン | N25: － | P25: 検索対象とするビル名を選択する。
H26: － | K26: 選択 | P26: － | T26: － | X26: ”--選択してください--” （※３）
B27: 8 | C27: グループ名 | H27: プルダウン | N27: － | P27: 検索対象とするグループ名を選択する。
H28: － | K28: 選択 | P28: － | T28: － | X28: ”--選択してください--”
B29: 9 | C29: 会社名 | H29: プルダウン | N29: － | P29: 検索対象とする会社名を選択する。
H30: － | K30: 選択 | P30: － | T30: － | X30: ”--選択してください--”
B31: 10 | C31: 組織名 | H31: プルダウン | N31: － | P31: 検索対象とする組織名を選択する。
H32: － | K32: 選択 | P32: － | T32: － | X32: ”--選択してください--”
B33: 11 | C33: 住所 | H33: テキスト | N33: － | P33: 検索対象とする住所を入力する。
H34: － | K34: 入力 | P34: 全半角 | T34: 200 | X34: 空欄
B35: 12 | C35: フリー項目１～５ | H35: プルダウン | N35: － | P35: 検索対象とするフリー項目５を選択する。
H36: － | K36: 選択 | P36: － | T36: － | X36: ”--選択してください--”
B37: 13 | C37: 最終更新日時 （開始） | H37: テキスト／カレンダー | N37: － | P37: 検索対象とする最終更新日時（開始）指定／２．３．１ 共通機能 ２．３．１．１ 共通処理参照
H38: － | K38: 入力 | P38: 年月日時分 | T38: yyyy/mm/dd hh:mm | X38: 空欄
B39: 14 | C39: 最終更新日時 （終了） | H39: テキスト／カレンダー | N39: － | P39: 検索対象とする最終更新日時（終了）指定／２．３．１ 共通機能 ２．３．１．１ 共通処理参照
H40: － | K40: 入力 | P40: 年月日時分 | T40: yyyy/mm/dd hh:mm | X40: 空欄
B41: 15 | C41: 検索 | H41: ボタン | N41: － | P41: 検索項目の入力内容に従って検索を行い、結果を一覧で表示する。
H42: － | K42: － | P42: － | T42: － | X42: －
...

Sheet ビルデータ登録画面_1
A1: システム名 | D1: =目次!D1 -> 備蓄品管理システム | T1: Ｖｅｒ. | V1: 1.0
A2: =目次!A2 -> 章番号 | D2: =目次!D2 -> 第２章 画面設計 | T2: 作成日 | V2: 42398
A3: =目次!A3 -> 機能名 | T3: 作成者 | V3: 協和エクシオ
A4: =目次!A4 -> ２．３．７ ビルデータ登録 | T4: 更新日
T5: 更新者
A6: 画面名 | D6: =目次!D10 -> ２．３．７．２ ビルデータ登録 | O6: ＩＤ
B8: 【1】画面定義
B47: (1/2)
B48: № | C48: 説 明
B49: 1 | C49: 【ビルデータ登録エリア】
C50: ・ ビルデータ情報を新規登録する。
C52: [登録ボタン]
C53: ボタン押下で、ビルデータ情報を新規登録する。
C54: ・ 登録確認ダイアログを表示する。
C55: ・ 新規登録後、ビルデータ詳細画面へ遷移する。
C56: [クリアボタン]
C57: ボタン押下で、画面内入力項目を初期表示時の状態に戻す。
B67: (2/2)
B68: № | C68: 説 明
B69: 2 | C69: 【ユーザ権限によるデータの利用範囲】
C70: ・ ログインユーザの権限（ユーザレベル）により、データ利用の範囲を制限する。
D71: 「２．３．７．６ 別紙＿権限」を参照

Sheet ビルデータ登録画面_2
A1: システム名 | I1: 章番号 | P1: 機能名 | Z1: Ｖｅｒ. | AC1: 1.0
A2: =目次!D1 -> 備蓄品管理システム | I2: =目次!D2 -> 第２章 画面設計 | P2: =目次!A4 -> ２．３．７ ビルデータ登録 | Z2: 作成日 | AC2: 42398 | AF2: 作成者 | AI2: 協和エクシオ
Z3: 更新日 | AF3: 更新者
A4: 画面名 | I4: =目次!D10 -> ２．３．７．２ ビルデータ登録 | Z4: 画面ＩＤ
B6: 【2】画面項目定義
B8: № | C8: 項目名 | H8: ｺﾝﾎﾟｰﾈﾝﾄ種別 | N8: 必須 入力 | P8: 項目説明
H9: 出力形式 | K9: 入力形式 | P9: 属性 | T9: 最大文字数 | X9: 初期表示
C10: 【ヘッダーバー】 | N10: ２．３．１ 共通機能 ２．３．１．１ 共通処理参照
B11: 1 | C11: ヘッダー文言① | H11: テキストエリア | N11: － | P11: ログイン中のユーザ名を表示する。
H12: テキスト | K12: － | P12: － | T12: － | X12: ”ユーザ名：” + ログイン中のユーザ名
B13: 2 | C13: ヘッダー文言② | H13: テキストエリア | N13: － | P13: ログイン中のユーザ名が所属する組織名を表示する。
H14: テキスト | K14: － | P14: － | T14: － | X14: ”組織名：” + ログイン中のユーザの組織名
B15: 3 | C15: ヘッダー文言③ | H15: テキストエリア | N15: － | P15: 非表示。
H16: テキスト | K16: － | P16: － | T16: － | X16: 非表示
B17: 4 | C17: 前に戻る | H17: ボタン | N17: － | P17: 前画面に戻る。
H18: － | K18: － | P18: － | T18: － | X18: －
C19: 【メッセージエリア】
B20: 5 | C20: メッセージエリア | H20: テキストエリア | N20: － | P20: エラーがあった場合は、エラーの内容を表示（※１）する。
H21: テキスト | K21: － | P21: － | T21: － | X21: 非表示
C22: 【ビルデータ登録エリア】
B23: 6 | C23: 登録 | H23: ボタン | N23: － | P23: 入力値のチェックを行いビルデータ情報を登録する。既に登録済記録と重複（同一ビルコード／同一会社名）する場合はエラーとして登録できない。
H25: － | K25: － | P25: － | T25: － | X25: －
B26: 7 | C26: クリア | H26: ボタン | N26: － | P26: 各入力項目を初期表示時の状態に戻す。
H27: － | K27: － | P27: － | T27: － | X27: －
B28: 8 | C28: ビルコード | H28: テキスト | N28: ○ | P28: 検索対象とするビルコードを入力する。
H29: － | K29: 入力 | P29: 数字 | T29: 4 | X29: 空欄
B30: 9 | C30: ビル名 | H30: テキスト | N30: ○ | P30: ビル名を入力する。
H31: － | K31: 入力 | P31: 全半角 | T31: 50 | X31: 空欄
B32: 10 | C32: グループ名 | H32: プルダウン（※２） | N32: － | P32: グループ名を選択する。
H33: － | K33: 選択 | P33: － | T33: － | X33: 選択可能な組織名が複数の場合、
X34: ”--選択してください--”
X35: 選択可能な組織名が単一の場合、
X36: グループ名
B37: 11 | C37: 会社名 | H37: プルダウン（※２） | N37: － | P37: 会社名を選択する。
H38: － | K38: 選択 | P38: － | T38: － | X38: 選択可能な組織名が複数の場合、
X39: ”--選択してください--”
X40: 選択可能な組織名が単一の場合、
X41: 会社名
B42: 12 | C42: 組織名 （選択／入力） | H42: ラジオボタン | N42: ○ | P42: 組織名の入力方法（選択形式／入力形式）を選択する。
H43: － | K43: 選択 | P43: － | T43: － | X43: ”選択”にチェック
...

Sheet ビルデータ詳細画面_1
A1: システム名 | D1: =目次!D1 -> 備蓄品管理システム | T1: Ｖｅｒ. | V1: 1.0
A2: =目次!A2 -> 章番号 | D2: =目次!D2 -> 第２章 画面設計 | T2: 作成日 | V2: 42398
A3: =目次!A3 -> 機能名 | T3: 作成者 | V3: 協和エクシオ
A4: =目次!A4 -> ２．３．７ ビルデータ登録 | T4: 更新日
T5: 更新者
A6: 画面名 | D6: =目次!D12 -> ２．３．７．３ ビルデータ詳細 | O6: ＩＤ
B8: 【1】画面定義
B46: (1/2)
B47: № | C47: 説 明
B48: 1 | C48: 【ビルデータ詳細エリア】
C49: ・ 前画面にて指定されたビルコードから、ビルデータ情報を表示する。
C51: [修正ボタン]
C52: ボタン押下で、指定したビルコードのビルデータ修正画面へ遷移する。
C53: [削除ボタン]
C54: ボタン押下で、指定したビルコードのビルデータ情報を削除する。
C55: ・ 削除確認ダイアログを表示する。
C56: ・ 削除完了後、ビルデータ一覧画面へ遷移する。
C57: ※当該組織コード／ビルコード／会社IDに紐づく、ユーザ情報が登録済みの場合、
C58: ※当該ビルコード／会社IDに紐づく、ユーザ情報、被災状況情報、備蓄品情報が | D58: 削除はできない。
C59: ※当該組織コード／ビルコード／会社IDに紐づく、被災状況情報、または備蓄品情報が
D60: 登録済の場合については、削除を可能とするが、情報が登録済みであることを
D61: 実行確認ダイアログで通知させる。
C62: ※削除実行を選択した場合は、被災状況情報、備蓄品情報も同時に削除する。
B66: (2/2)
B67: № | C67: 説 明
B68: 2 | C68: 【ユーザ権限によるデータの利用範囲】
C69: ・ ログインユーザの権限（ユーザレベル）により、データ利用の範囲を制限する。
D70: 「２．３．７．６ 別紙＿権限」を参照

Sheet ビルデータ詳細画面_2
A1: システム名 | I1: 章番号 | P1: 機能名 | Z1: Ｖｅｒ. | AC1: 1.0
A2: =目次!D1 -> 備蓄品管理システム | I2: =目次!D2 -> 第２章 画面設計 | P2: =目次!A4 -> ２．３．７ ビルデータ登録 | Z2: 作成日 | AC2: 42398 | AF2: 作成者 | AI2: 協和エクシオ
Z3: 更新日 | AF3: 更新者
A4: 画面名 | I4: =目次!D12 -> ２．３．７．３ ビルデータ詳細 | Z4: 画面ＩＤ
B6: 【2】画面項目定義
B8: № | C8: 項目名 | H8: ｺﾝﾎﾟｰﾈﾝﾄ種別 | N8: 必須 入力 | P8: 項目説明
H9: 出力形式 | K9: 入力形式 | P9: 属性 | T9: 最大文字数 | X9: 初期表示
C10: 【ヘッダーバー】 | N10: ２．３．１ 共通機能 ２．３．１．１ 共通処理参照
B11: 1 | C11: ヘッダー文言① | H11: テキストエリア | N11: － | P11: ログイン中のユーザ名を表示する。
H12: テキスト | K12: － | P12: － | T12: － | X12: ”ユーザ名：” + ログイン中のユーザ名
B13: 2 | C13: ヘッダー文言② | H13: テキストエリア | N13: － | P13: ログイン中のユーザ名が所属する組織名を表示する。
H14: テキスト | K14: － | P14: － | T14: － | X14: ”組織名：” + ログイン中のユーザの組織名
B15: 3 | C15: ヘッダー文言③ | H15: テキストエリア | N15: － | P15: 非表示。
H16: テキスト | K16: － | P16: － | T16: － | X16: 非表示
B17: 4 | C17: 前に戻る | H17: ボタン | N17: － | P17: 前画面に戻る。
H18: － | K18: － | P18: － | T18: － | X18: －
C19: 【メッセージエリア】
B20: 5 | C20: メッセージエリア | H20: テキストエリア | N20: － | P20: エラーがあった場合は、エラーの内容を表示（※１）する。
H21: テキスト | K21: － | P21: － | T21: － | X21: 非表示
C22: 【ビルデータ詳細エリア】
B23: 6 | C23: 修正 | H23: ボタン（※２） | N23: － | P23: ビルデータ修正画面に遷移する。
H24: － | K24: － | P24: － | T24: － | X24: －
B25: 7 | C25: 削除 | H25: ボタン（※２） | N25: － | P25: 削除可否のチェックを行いエラーがなければ表示データを削除し、ビルデータ一覧画面へ戻る。
H26: － | K26: － | P26: － | T26: － | X26: －
B27: 8 | C27: ビルコード | H27: テキスト | N27: － | P27: ビルコードを表示する。
H28: テキスト | K28: － | P28: － | T28: － | X28: ビルコード
B29: 9 | C29: ビル名 | H29: テキスト | N29: － | P29: ビル名を表示する。
H30: テキスト | K30: － | P30: － | T30: － | X30: ビル名
B31: 10 | C31: グループ名 | H31: テキスト | N31: － | P31: グループ名を表示する。
H32: テキスト | K32: － | P32: － | T32: － | X32: グループ名
B33: 11 | C33: 会社名 | H33: テキスト | N33: － | P33: 会社名を表示する。
H34: テキスト | K34: － | P34: － | T34: － | X34: 会社名
B35: 12 | C35: 組織名 | H35: テキスト | N35: － | P35: 組織名を表示する。
H36: テキスト | K36: － | P36: － | T36: － | X36: 組織名
B37: 13 | C37: 正社員数 （社員） | H37: テキスト | N37: － | P37: 正社員数（社員）を表示する。
H38: － | K38: 入力 | P38: 数字 | T38: 5 | X38: 正社員数（社員）
B39: 14 | C39: 正社員数 （ＮＴＴ在籍出向者） | H39: テキスト | N39: － | P39: 正社員数（ＮＴＴ在籍出向者）を表示する。
H40: － | K40: 入力 | P40: 数字 | T40: 5 | X40: 正社員数（ＮＴＴ在籍出向者）
B41: 15 | C41: 正社員数 （他社出向者） | H41: テキスト | N41: － | P41: 正社員数（他社出向者）を表示する。
H42: － | K42: 入力 | P42: 数字 | T42: 5 | X42: 正社員数（他社出向者）
...

Sheet ビルデータ修正画面_1
A1: システム名 | D1: =目次!D1 -> 備蓄品管理システム | T1: Ｖｅｒ. | V1: 1.0
A2: =目次!A2 -> 章番号 | D2: =目次!D2 -> 第２章 画面設計 | T2: 作成日 | V2: 42398
A3: =目次!A3 -> 機能名 | T3: 作成者 | V3: 協和エクシオ
A4: =目次!A4 -> ２．３．７ ビルデータ登録 | T4: 更新日
T5: 更新者
A6: 画面名 | D6: =目次!D14 -> ２．３．７．４ ビルデータ修正 | O6: ＩＤ
B8: 【1】画面定義
B48: (1/2)
B49: № | C49: 説 明
B50: 1 | C50: 【ビルデータ修正エリア】
C51: ・ 前画面にて指定されたビルコードから、ビルデータ情報を初期表示する。
C53: [登録ボタン]
C54: ボタン押下で、ビルデータ情報を修正登録する。
C55: ・ 修正登録確認ダイアログを表示する。
C56: ・ 修正登録後、ビルデータ詳細画面へ遷移する。
C57: [クリアボタン]
C58: ボタン押下で、画面内入力項目を初期表示時の状態に戻す。
B68: (2/2)
B69: № | C69: 説 明
B70: 2 | C70: 【ユーザ権限によるデータの利用範囲】
C71: ・ ログインユーザの権限（ユーザレベル）により、データ利用の範囲を制限する。
D72: 「２．３．７．６ 別紙＿権限」を参照

Sheet ビルデータ修正画面_2
A1: システム名 | I1: 章番号 | P1: 機能名 | Z1: Ｖｅｒ. | AC1: 1.0
A2: =目次!D1 -> 備蓄品管理システム | I2: =目次!D2 -> 第２章 画面設計 | P2: =目次!A4 -> ２．３．７ ビルデータ登録 | Z2: 作成日 | AC2: 42398 | AF2: 作成者 | AI2: 協和エクシオ
Z3: 更新日 | AF3: 更新者
A4: 画面名 | I4: =目次!D14 -> ２．３．７．４ ビルデータ修正 | Z4: 画面ＩＤ
B6: 【2】画面項目定義
B8: № | C8: 項目名 | H8: ｺﾝﾎﾟｰﾈﾝﾄ種別 | N8: 必須 入力 | P8: 項目説明
H9: 出力形式 | K9: 入力形式 | P9: 属性 | T9: 最大文字数 | X9: 初期表示
C10: 【ヘッダーバー】 | N10: ２．３．１ 共通機能 ２．３．１．１ 共通処理参照
B11: 1 | C11: ヘッダー文言① | H11: テキストエリア | N11: － | P11: ログイン中のユーザ名を表示する。
H12: テキスト | K12: － | P12: － | T12: － | X12: ”ユーザ名：” + ログイン中のユーザ名
B13: 2 | C13: ヘッダー文言② | H13: テキストエリア | N13: － | P13: ログイン中のユーザ名が所属する組織名を表示する。
H14: テキスト | K14: － | P14: － | T14: － | X14: ”組織名：” + ログイン中のユーザの組織名
B15: 3 | C15: ヘッダー文言③ | H15: テキストエリア | N15: － | P15: 非表示。
H16: テキスト | K16: － | P16: － | T16: － | X16: 非表示
B17: 4 | C17: 前に戻る | H17: ボタン | N17: － | P17: 前画面に戻る。
H18: － | K18: － | P18: － | T18: － | X18: －
C19: 【メッセージエリア】
B20: 5 | C20: メッセージエリア | H20: テキストエリア | N20: － | P20: エラーがあった場合は、エラーの内容を表示（※１）する。
H21: テキスト | K21: － | P21: － | T21: － | X21: 非表示
C22: 【ビルデータ修正エリア】
B23: 6 | C23: 登録 | H23: ボタン | N23: － | P23: 入力値のチェックを行い、問題ない場合はビルデータ情報を修正登録する。
H24: － | K24: － | P24: － | T24: － | X24: －
B25: 7 | C25: クリア | H25: ボタン | N25: － | P25: 各入力項目を初期表示時の状態に戻す。
H26: － | K26: － | P26: － | T26: － | X26: －
B27: 8 | C27: ビルコード | H27: テキスト | N27: － | P27: ビルコードを表示する。
H28: テキスト | K28: － | P28: － | T28: － | X28: ビルコード
B29: 9 | C29: ビル名 | H29: テキスト | N29: ○ | P29: ビル名を入力する。
H30: － | K30: 入力 | P30: 全半角 | T30: 50 | X30: ビル名
B31: 10 | C31: グループ名 | H31: プルダウン（※２） | N31: － | P31: グループ名を選択する。
H32: － | K32: 選択 | P32: － | T32: － | X32: 選択可能な組織名が複数の場合、
X33: ”--選択してください--”
X34: 選択可能な組織名が単一の場合、
X35: グループ名
B36: 11 | C36: 会社名 | H36: プルダウン（※２） | N36: － | P36: 会社名を選択する。
H37: － | K37: 選択 | P37: － | T37: － | X37: 選択可能な組織名が複数の場合、
X38: ”--選択してください--”
X39: 選択可能な組織名が単一の場合、
X40: 会社名
B41: 12 | C41: 組織名 （選択／入力） | H41: ラジオボタン | N41: ○ | P41: 組織名の入力方法（選択形式／入力形式）を選択する。
H42: － | K42: 選択 | P42: － | T42: － | X42: ”選択”にチェック
...

Sheet ビルデータCSV登録画面_1
A1: システム名 | D1: =目次!D1 -> 備蓄品管理システム | T1: Ｖｅｒ. | V1: 1.0
A2: =目次!A2 -> 章番号 | D2: =目次!D2 -> 第２章 画面設計 | T2: 作成日 | V2: 42398
A3: =目次!A3 -> 機能名 | T3: 作成者 | V3: 協和エクシオ
A4: =目次!A4 -> ２．３．７ ビルデータ登録 | T4: 更新日
T5: 更新者
A6: 画面名 | D6: =目次!D16 -> ２．３．７．５ ビルデータCSV登録 | O6: ＩＤ
B8: 【1】画面定義
B28: (1/2)
B29: № | C29: 説 明
B30: 1 | C30: 【ビルデータCSV登録エリア】
C31: ・ 指定したCSVファイルの情報をビルデータ情報に一括登録する。
C33: [参照ボタン]
C34: ボタン押下で、ビルデータ情報登録用CSVファイルの指定を行う。
C35: ・ ファイル選択ダイアログを開く。
C36: ・ ファイル選択ダイアログにてビルデータ情報登録用CSVファイルの指定を行う。
C37: ・ ”開く”ボタンを押すことで、CSVファイル欄に指定したファイル名を表示する。
C38: [登録ボタン]
C39: ボタン押下で、CSVファイル欄に指定したファイルの情報を一括登録する。
D40: ※選択した組織名とCSVファイルの組織名が合致するレコードのみを処理対象とし、
D41: 一致しないレコードについては処理対象外として読み飛ばす。
C42: ・ 一括登録確認ダイアログを表示する。
C43: ・ CSVファイルについて、拡張子やファイルサイズのチェックを行う。
C44: ・ CSVファイル内のデータについて、レイアウトや必須、属性、桁数等のチェックを行う。
C45: ・ チェックに問題なければDBにビルデータ情報を登録する。
D46: ※項目の設定に誤りがある場合はエラー情報をファイルに出力して登録しない。
C47: [登録・更新方法について]
C48: ・ 以下の条件で登録、更新の判断をする。
E49: 登録・更新条件 | T49: 登録・更新
E50: 組織名／ビルコード／会社名が一致する未削除のビルデータ情報がDBに存在しない。 | T50: 登録
E52: 上記以外。 | T52: 更新
E53: ※削除については実施しない。
C54: [クリアボタン]
C55: ボタン押下で、CSVファイル欄の項目を初期表示時の状態に戻す。
B60: (2/2)
B61: № | C61: 説 明
B62: 2 | C62: 【ユーザ権限によるデータの利用範囲】
C63: ・ ログインユーザの権限（ユーザレベル）により、データ利用の範囲を制限する。
D64: 「２．３．７．６ 別紙＿権限」を参照

Sheet ビルデータCSV登録画面_2
A1: システム名 | I1: 章番号 | P1: 機能名 | Z1: Ｖｅｒ. | AC1: 1.0
A2: =目次!D1 -> 備蓄品管理システム | I2: =目次!D2 -> 第２章 画面設計 | P2: =目次!A4 -> ２．３．７ ビルデータ登録 | Z2: 作成日 | AC2: 42398 | AF2: 作成者 | AI2: 協和エクシオ
Z3: 更新日 | AF3: 更新者
A4: 画面名 | I4: =目次!D16 -> ２．３．７．５ ビルデータCSV登録 | Z4: 画面ＩＤ
B6: 【2】画面項目定義
B8: № | C8: 項目名 | H8: ｺﾝﾎﾟｰﾈﾝﾄ種別 | N8: 必須 入力 | P8: 項目説明
H9: 出力形式 | K9: 入力形式 | P9: 属性 | T9: 最大文字数 | X9: 初期表示
C10: 【ヘッダーバー】 | N10: ２．３．１ 共通機能 ２．３．１．１ 共通処理参照
B11: 1 | C11: ヘッダー文言① | H11: テキストエリア | N11: － | P11: ログイン中のユーザ名を表示する。
H12: テキスト | K12: － | P12: － | T12: － | X12: ”ユーザ名：” + ログイン中のユーザ名
B13: 2 | C13: ヘッダー文言② | H13: テキストエリア | N13: － | P13: ログイン中のユーザ名が所属する組織名を表示する。
H14: テキスト | K14: － | P14: － | T14: － | X14: ”組織名：” + ログイン中のユーザの組織名
B15: 3 | C15: ヘッダー文言③ | H15: テキストエリア | N15: － | P15: 非表示。
H16: テキスト | K16: － | P16: － | T16: － | X16: 非表示
B17: 4 | C17: 前に戻る | H17: ボタン | N17: － | P17: 前画面に戻る。
H18: － | K18: － | P18: － | T18: － | X18: －
C19: 【メッセージエリア】
B20: 5 | C20: メッセージエリア | H20: テキストエリア | N20: － | P20: エラーがあった場合は、エラーの内容を表示（※１）する。
H21: テキスト | K21: － | P21: － | T21: － | X21: 非表示
C22: 【ビルデータCSV登録エリア】
B23: 6 | C23: 参照 | H23: ボタン | N23: － | P23: 押下でファイル選択ダイアログを表示する。
H24: － | K24: － | P24: － | T24: － | X24: －
B25: 7 | C25: 登録 | H25: ボタン | N25: － | P25: 入力値のチェックを行い、問題ない場合はCSVファイルからビルデータ情報を一括登録する。
H26: － | K26: － | P26: － | T26: － | X26: －
B27: 8 | C27: クリア | H27: ボタン | N27: － | P27: CSVファイル欄に設定された値を初期表示時の状態に戻す。
H28: － | K28: － | P28: － | T28: － | X28: －
B29: 9 | C29: グループ名 | H29: プルダウン（※２） | N29: ○ | P29: ビルデータを紐付けるグループ名を選択する。
H30: － | K30: 選択 | P30: － | T30: － | X30: 選択可能な組織名が複数の場合、
X31: ”--選択してください--”
X32: 選択可能な組織名が単一の場合、
X33: グループ名
B34: 10 | C34: 会社名 | H34: プルダウン（※２） | N34: ○ | P34: ビルデータを紐付ける会社名を選択する。
H35: － | K35: 選択 | P35: － | T35: － | X35: 選択可能な組織名が複数の場合、
X36: ”--選択してください--”
X37: 選択可能な組織名が単一の場合、
X38: 会社名
B39: 11 | C39: CSVファイル | H39: テキスト | N39: － | P39: 取り込むCSVファイルのパス付き名称を表示する。
H40: － | K40: － | P40: － | T40: － | X40: 空欄
B42: ※１ エラーメッセージの表示場所については、「標準化設計」を参照のこと。
B43: ※２ プルダウンに表示する値は、ログインしたユーザの権限（ユーザレベル）により、利用可能な場合は表示し、それ以外は非表示とすること。
