Workbook

Sheet 目次
A1: システム名 | D1: 備蓄品管理システム | T1: Ｖｅｒ. | V1: 1.0 | AA1: 章 | AC1: 節 | AE1: 項
A2: 章番号 | D2: ="第"&DBCS($AA$3)&"章 "&AB3 -> 第３章 機能設計 | T2: 作成日 | V2: 2016/1/29 | AA2: 番 | AB2: 章分類 | AC2: 番 | AD2: 節分類 | AE2: 番 | AF2: 機能名
A3: 機能名 | T3: 作成者 | V3: 協和エクシオ | AA3: 3 | AB3: 機能設計 | AC3: 1 | AD3: 機能詳細 | AE3: 4 | AF3: 被災状況登録
A4: =IF($AA$3="","",DBCS($AA$3))&IF($AC$3="","",DBCS("."&$AC$3))&IF($AE$3="","",DBCS("."&$AE$3))&DBCS(" ")&$AF$3 -> ３．１．４ 被災状況登録 | T4: 更新日
T5: 更新者
AA6: 段
AA7: 番 | AB7: 処理名
D8: =IF($AA8="","",IF($AA$3="","",DBCS($AA$3))&IF($AC$3="","",DBCS("."&$AC$3))&IF($AE$3="","",DBCS("."&$AE$3))&IF($AA8="","",DBCS("."&$AA8))&DBCS(" ")&$AB8) -> ３．１．４．１ 被災状況一覧 | AA8: 1 | AB8: 被災状況一覧
D10: =IF($AA10="","",IF($AA$3="","",DBCS($AA$3))&IF($AC$3="","",DBCS("."&$AC$3))&IF($AE$3="","",DBCS("."&$AE$3))&IF($AA10="","",DBCS("."&$AA10))&DBCS(" ")&$AB10) -> ３．１．４．２ 被災状況登録 | AA10: 2 | AB10: 被災状況登録
D12: =IF($AA12="","",IF($AA$3="","",DBCS($AA$3))&IF($AC$3="","",DBCS("."&$AC$3))&IF($AE$3="","",DBCS("."&$AE$3))&IF($AA12="","",DBCS("."&$AA12))&DBCS(" ")&$AB12) -> ３．１．４．３ 被災状況詳細 | AA12: 3 | AB12: 被災状況詳細
D14: =IF($AA14="","",IF($AA$3="","",DBCS($AA$3))&IF($AC$3="","",DBCS("."&$AC$3))&IF($AE$3="","",DBCS("."&$AE$3))&IF($AA14="","",DBCS("."&$AA14))&DBCS(" ")&$AB14) -> ３．１．４．４ 被災状況修正 | AA14: 4 | AB14: 被災状況修正
D16: =IF($AA16="","",IF($AA$3="","",DBCS($AA$3))&IF($AC$3="","",DBCS("."&$AC$3))&IF($AE$3="","",DBCS("."&$AE$3))&IF($AA16="","",DBCS("."&$AA16))&DBCS(" ")&$AB16) -> ３．１．４．５ 被災状況履歴 | AA16: 5 | AB16: 被災状況履歴
D18: =IF($AA18="","",IF($AA$3="","",DBCS($AA$3))&IF($AC$3="","",DBCS("."&$AC$3))&IF($AE$3="","",DBCS("."&$AE$3))&IF($AA18="","",DBCS("."&$AA18))&DBCS(" ")&$AB18) -> ３．１．４．６ 被災状況追加報告 | AA18: 6 | AB18: 被災状況追加報告
D20: =IF($AA20="","",IF($AA$3="","",DBCS($AA$3))&IF($AC$3="","",DBCS("."&$AC$3))&IF($AE$3="","",DBCS("."&$AE$3))&IF($AA20="","",DBCS("."&$AA20))&DBCS(" ")&$AB20) -> ３．１．４．７ 被災状況CSV登録 | AA20: 7 | AB20: 被災状況CSV登録
D22: =IF($AA22="","",IF($AA$3="","",DBCS($AA$3))&IF($AC$3="","",DBCS("."&$AC$3))&IF($AE$3="","",DBCS("."&$AE$3))&IF($AA22="","",DBCS("."&$AA22))&DBCS(" ")&$AB22)
D24: =IF($AA24="","",IF($AA$3="","",DBCS($AA$3))&IF($AC$3="","",DBCS("."&$AC$3))&IF($AE$3="","",DBCS("."&$AE$3))&IF($AA24="","",DBCS("."&$AA24))&DBCS(" ")&$AB24)
D26: =IF($AA26="","",IF($AA$3="","",DBCS($AA$3))&IF($AC$3="","",DBCS("."&$AC$3))&IF($AE$3="","",DBCS("."&$AE$3))&IF($AA26="","",DBCS("."&$AA26))&DBCS(" ")&$AB26)
D28: =IF($AA28="","",IF($AA$3="","",DBCS($AA$3))&IF($AC$3="","",DBCS("."&$AC$3))&IF($AE$3="","",DBCS("."&$AE$3))&IF($AA28="","",DBCS("."&$AA28))&DBCS(" ")&$AB28)
D30: =IF($AA30="","",IF($AA$3="","",DBCS($AA$3))&IF($AC$3="","",DBCS("."&$AC$3))&IF($AE$3="","",DBCS("."&$AE$3))&IF($AA30="","",DBCS("."&$AA30))&DBCS(" ")&$AB30)
D32: =IF($AA32="","",IF($AA$3="","",DBCS($AA$3))&IF($AC$3="","",DBCS("."&$AC$3))&IF($AE$3="","",DBCS("."&$AE$3))&IF($AA32="","",DBCS("."&$AA32))&DBCS(" ")&$AB32)
D34: =IF($AA34="","",IF($AA$3="","",DBCS($AA$3))&IF($AC$3="","",DBCS("."&$AC$3))&IF($AE$3="","",DBCS("."&$AE$3))&IF($AA34="","",DBCS("."&$AA34))&DBCS(" ")&$AB34)

Sheet 被災状況一覧
A1: システム名 | D1: =目次!D1 -> 備蓄品管理システム | T1: Ｖｅｒ. | V1: 1.0
A2: =目次!A2 -> 章番号 | D2: =目次!D2 -> 第３章 機能設計 | T2: 作成日 | V2: 42398
A3: =目次!A3 -> 機能名 | T3: 作成者 | V3: 協和エクシオ
A4: =目次!A4 -> ３．１．４ 被災状況登録 | T4: 更新日
T5: 更新者
A6: 画面名 | D6: =目次!D8 -> ３．１．４．１ 被災状況一覧 | O6: ＩＤ
B8: 【1】イベント 1/6
B10: № | C10: 項目名 | I10: トリガー
C11: 処理内容
B12: 1 | C12: ― | I12: 初期表示
C13: ＜1.1 前提条件＞
D14: 1.1.1 | E14: 地図画面より遷移する。
D15: 1.1.2 | E15: 被災状況登録画面より遷移する。
D16: 1.1.3 | E16: 被災状況詳細画面より遷移する。
D17: 1.1.4 | E17: 被災状況CSV登録画面より遷移する。
D18: 1.1.5 | E18: 各画面のメニューバーから遷移する。
C20: ＜1.2 初期処理＞
D21: 1.2.1 | E21: 画面入力項目を初期化する。
D22: 1.2.2 | E22: メッセージエリアを初期化する。
D23: 1.2.3 | E23: ヘッダーバーを初期化する。
F24: ・ ログイン中ユーザのユーザ名と組織名１をDBから取得する。
F25: ・ ユーザ名をヘッダー文言①に、組織名１をヘッダー文言②に表示する。
D26: 1.2.4 | E26: 災害名プルダウンを、DBに登録された未削除の災害情報から生成する。
F27: ・ 災害発生日時／災害IDの降順でソートする。
F28: ・ 初期値として、地図画面で表示中の災害名を表示する。
D29: 1.2.5 | E29: グループ名プルダウンの生成方法を「2.3.2 共通権限」の2.1を参照する。
F30: ・ 初期値として”--選択してください--”を選択状態にする。
D31: 1.2.6 | E31: 会社名プルダウンの生成方法を「2.3.2 共通権限」の2.1を参照する。
F32: ・ 初期値として”--選択してください--”を選択状態にする。
D33: 1.2.7 | E33: 組織名プルダウンの生成方法を「2.3.2 共通権限」の2.1を参照する。
F34: ・ 初期値として”--選択してください--”を選択状態にする。
D35: 1.2.8 | E35: ビル名プルダウンの生成方法を「2.3.2 共通権限」の2.1を参照する。
F36: ・ 初期値として”--選択してください--”を選択状態にする。
B43: 【1】イベント 2/6
B45: № | C45: 項目名 | I45: トリガー
C46: 処理内容
B47: 1 | D47: 1.2.9 | E47: 災害名プルダウンが”未選択”状態の場合、以下の処理を行い、処理を抜ける。
F48: ・ 災害名未選択メッセージを、メッセージエリアに表示する。（ED0006）
G49: 「災害名が選択されていません。」
F50: ・ 被災状況情報件数０件を、ヘッダー文言③に表示する。
...

Sheet 被災状況登録
A1: システム名 | D1: =目次!D1 -> 備蓄品管理システム | T1: Ｖｅｒ. | V1: 1.0
A2: =目次!A2 -> 章番号 | D2: =目次!D2 -> 第３章 機能設計 | T2: 作成日 | V2: 42398
A3: =目次!A3 -> 機能名 | T3: 作成者 | V3: 協和エクシオ
A4: =目次!A4 -> ３．１．４ 被災状況登録 | T4: 更新日
T5: 更新者
A6: 画面名 | D6: =目次!D10 -> ３．１．４．２ 被災状況登録 | O6: ＩＤ
B8: 【1】イベント 1/4
B10: № | C10: 項目名 | I10: トリガー
C11: 処理内容
B12: 1 | C12: ― | I12: 初期表示
C13: ＜1.1 前提条件＞
D14: 1.1.1 | E14: 被災状況一覧画面より遷移する。
C16: ＜1.2 初期処理＞
D17: 1.2.1 | E17: 画面入力項目を初期化する。
D18: 1.2.2 | E18: メッセージエリアを初期化する。
D19: 1.2.3 | E19: ヘッダーバーを初期化する。
F20: ・ ログイン中ユーザのユーザ名と組織名１をDBから取得する。
F21: ・ ユーザ名をヘッダー文言①に、組織名１をヘッダー文言②に表示する。
D22: 1.2.4 | E22: 災害名プルダウンを、DBに登録された未削除の災害情報から生成する。
F23: ・ 災害発生日時／災害IDの降順でソートする。
F24: ・ 初期値として、被災状況一覧画面で表示中の災害名を表示する。
D25: 1.2.10 | E25: グループ名プルダウンの生成方法を「2.3.2 共通権限」の2.2を参照する。
F26: ・ 初期値として”--選択してください--”を選択状態にする。
D27: 1.2.5 | E27: 会社名プルダウンの生成方法を「2.3.2 共通権限」の2.2を参照する。
F28: ・ 初期値として”--選択してください--”を選択状態にする。
D29: 1.2.6 | E29: 組織名プルダウンの生成方法を「2.3.2 共通権限」の2.2を参照する。
F30: ・ 初期値として”--選択してください--”を選択状態にする。
D31: 1.2.7 | E31: ビル名プルダウンの生成方法を「2.3.2 共通権限」の2.2を参照する。
F32: ・ 初期値として”--選択してください--”を選択状態にする。
B43: 【1】イベント 2/4
B45: № | C45: 項目名 | I45: トリガー
C46: 処理内容
D47: 1.2.8 | E47: ラジオボタンの初期値を設定する。
E48: 下記ラジオボタン項目について初期値として"被災なし"を選択状態にする。
F49: ・ 被災状況
E50: ・ 下記ラジオボタン項目について初期値として"使用可"を選択状態にする。
F51: ・ 電気／ガス／水道／通話・通信
D52: 1.2.9 | E52: 報告日時欄に（システム日付 + 00時00分）をセットする。
D53: 1.2.10 | E53: 報告者氏名にログイン中ユーザのユーザ名をセットする。
B55: 2 | C55: クリアボタン | I55: 押下時
...

Sheet 被災状況詳細
A1: システム名 | D1: =目次!D1 -> 備蓄品管理システム | T1: Ｖｅｒ. | V1: 1.0
A2: =目次!A2 -> 章番号 | D2: =目次!D2 -> 第３章 機能設計 | T2: 作成日 | V2: 42398
A3: =目次!A3 -> 機能名 | T3: 作成者 | V3: 協和エクシオ
A4: =目次!A4 -> ３．１．４ 被災状況登録 | T4: 更新日
T5: 更新者
A6: 画面名 | D6: =目次!D12 -> ３．１．４．３ 被災状況詳細 | O6: ＩＤ
B8: 【1】イベント 1/2
B10: № | C10: 項目名 | I10: トリガー
C11: 処理内容
B12: 1 | C12: ― | I12: 初期表示
C13: ＜1.1 前提条件＞
D14: 1.1.1 | E14: 被災状況一覧画面より遷移する。
D15: 1.1.2 | E15: 被災状況登録画面より遷移する。
D16: 1.1.3 | E16: 被災状況修正画面より遷移する。
D17: 1.1.4 | E17: 被災状況履歴画面より遷移する。
D18: 1.1.5 | E18: 被災状況追加報告画面より遷移する。
C20: ＜1.2 初期処理＞
D21: 1.2.1 | E21: ヘッダーバーを初期化する。
F22: ・ ログイン中ユーザのユーザ名と組織名１をDBから取得する。
F23: ・ ユーザ名をヘッダー文言①に、組織名１をヘッダー文言②に表示する。
D24: 1.2.2 | E24: 前画面にて指定された行の被災状況情報を抽出する。
D25: 1.2.3 | E25: DBに登録された未削除の災害情報から、災害IDに紐づく、災害情報を抽出する。
D26: 1.2.4 | E26: DBに登録された未削除のビルデータ情報から、
E27: 組織コード／ビルコード／会社IDに紐づく、ビルデータ情報を抽出する。
D28: 1.2.5 | E28: 修正ボタン、追加報告ボタン、削除ボタンの表示／非表示の切り替えを、
E29: ログイン中ユーザの権限（ユーザレベル）に従って行う。
D31: 1.2.6 | E31: 抽出したビルデータ情報のビル名を、ヘッダー文言③に表示する。
D32: 1.2.7 | E32: 抽出した災害情報／ビルデータ情報／被災状況情報を被災状況詳細エリアに表示する。
D33: 1.2.8 | E33: DBに過去の報告履歴が存在する場合、被災状況履歴画面リンクを表示する。
F34: ”第” + 報告回数 + ”回 ” + 報告日時
B36: 2 | C36: 修正ボタン | I36: クリック時
C37: ＜2.1 前提条件＞
D38: 2.1.1 | E38: 修正ボタンを押下する。
C40: ＜2.2 画面遷移処理＞
D41: 2.2.1 | E41: 指定した被災状況情報の被災状況修正画面へ遷移する。
B43: 3 | C43: 追加報告ボタン | I43: クリック時
C44: ＜3.1 前提条件＞
D45: 3.1.1 | E45: 追加報告ボタンを押下する。
C47: ＜3.2 画面遷移処理＞
D48: 3.2.1 | E48: 指定した被災状況情報の被災状況追加報告画面へ遷移する。
...

Sheet 被災状況修正
A1: システム名 | D1: =目次!D1 -> 備蓄品管理システム | T1: Ｖｅｒ. | V1: 1.0
A2: =目次!A2 -> 章番号 | D2: =目次!D2 -> 第３章 機能設計 | T2: 作成日 | V2: 42398
A3: =目次!A3 -> 機能名 | T3: 作成者 | V3: 協和エクシオ
A4: =目次!A4 -> ３．１．４ 被災状況登録 | T4: 更新日
T5: 更新者
A6: 画面名 | D6: =目次!D14 -> ３．１．４．４ 被災状況修正 | O6: ＩＤ
B8: 【1】イベント 1/2
B10: № | C10: 項目名 | I10: トリガー
C11: 処理内容
B12: 1 | C12: ― | I12: 初期表示
C13: ＜1.1 前提条件＞
D14: 1.1.1 | E14: 被災状況詳細画面より遷移する。
C16: ＜1.2 初期処理＞
D17: 1.2.1 | E17: 画面入力項目を初期化する。
D18: 1.2.2 | E18: メッセージエリアを初期化する。
D19: 1.2.3 | E19: ヘッダーバーを初期化する。
F20: ・ ログイン中ユーザのユーザ名と組織名１をDBから取得する。
F21: ・ ユーザ名をヘッダー文言①に、組織名１をヘッダー文言②に表示する。
D22: 1.2.4 | E22: 前画面にて指定された災害ID／グループコード／会社コード／組織コード／ビルコード／
E23: 報告回数から、被災状況情報を抽出する。
D24: 1.2.5 | E24: DBに登録された未削除の災害情報から、災害IDに紐づく、災害情報を抽出する。
D25: 1.2.6 | E25: DBに登録された未削除のビルデータ情報から、
E26: 組織コード／ビルコード／会社IDに紐づく、ビルデータ情報を抽出する。
D27: 1.2.7 | E27: 抽出したビルデータ情報のビル名を、ヘッダー文言③に表示する。
D28: 1.2.8 | E28: 抽出した災害情報／ビルデータ情報／被災状況情報を、
E29: 被災状況修正エリアに初期表示する。
B31: 2 | C31: クリアボタン | I31: 押下時
C32: ＜2.1 前提条件＞
D33: 2.1.1 | E33: クリアボタンを押下する。
C35: ＜2.2 クリア処理＞
D36: 2.2.1 | E36: 確認ダイアログを表示する。（NA0001)
E37: 「入力情報をクリアします。よろしいですか？」OK・キャンセル
F38: OK押下： 次の処理（2.2.2）へ進む。
F39: キャンセル押下： 処理を抜ける。
D40: 2.2.2 | E40: すべての入力（プルダウン、ラジオボタン含む）項目を初期表示時の状態に戻す。
D41: 2.2.3 | E41: メッセージエリアを初期化する。
B60: 【1】イベント 2/2
B62: № | C62: 項目名 | I62: トリガー
C63: 処理内容
B64: 3 | C64: 登録ボタン | I64: 押下時
...

Sheet 被災状況履歴
A1: システム名 | D1: =目次!D1 -> 備蓄品管理システム | T1: Ｖｅｒ. | V1: 1.0
A2: =目次!A2 -> 章番号 | D2: =目次!D2 -> 第３章 機能設計 | T2: 作成日 | V2: 42398
A3: =目次!A3 -> 機能名 | T3: 作成者 | V3: 協和エクシオ
A4: =目次!A4 -> ３．１．４ 被災状況登録 | T4: 更新日
T5: 更新者
A6: 画面名 | D6: =目次!D16 -> ３．１．４．５ 被災状況履歴 | O6: ＩＤ
B8: 【1】イベント 1/2
B10: № | C10: 項目名 | I10: トリガー
C11: 処理内容
B12: 1 | C12: ― | I12: 初期表示
C13: ＜1.1 前提条件＞
D14: 1.1.1 | E14: 被災状況詳細画面より遷移する。
C16: ＜1.2 初期処理＞
D17: 1.2.1 | E17: ヘッダーバーを初期化する。
F18: ・ ログイン中ユーザのユーザ名と組織名１をDBから取得する。
F19: ・ ユーザ名をヘッダー文言①に、組織名１をヘッダー文言②に表示する。
D20: 1.2.2 | E20: 前画面にて指定された災害ID／組織コード／ビルコード／会社ID／報告回数から、
E21: 被災状況情報（履歴）を抽出する。
D22: 1.2.3 | E22: DBに登録された未削除の災害情報から、災害IDに紐づく、災害情報を抽出する。
D23: 1.2.4 | E23: DBに登録された未削除のビルデータ情報から、
E24: グループコード／会社コード／組織コードに紐づく、ビルデータ情報を抽出する。
D25: 1.2.5 | E25: 抽出したビルデータ情報のビル名を、ヘッダー文言③に表示する。
D26: 1.2.6 | E26: 抽出した災害情報／ビルデータ情報／被災状況情報（履歴）を、
E27: 被災状況履歴エリアに初期表示する。
B29: 2 | C29: 閉じるボタン | I29: クリック時
C30: ＜2.1 前提条件＞
D31: 2.1.1 | E31: 閉じるボタンを押す。
C33: ＜2.2 タブを閉じる処理＞
D34: 2.2.1 | E34: 本ウインドウのタブを閉じる。
B60: 【2】チェック処理 1/1
B62: チェックなし

Sheet 被災状況追加報告
A1: システム名 | D1: =目次!D1 -> 備蓄品管理システム | T1: Ｖｅｒ. | V1: 1.0
A2: =目次!A2 -> 章番号 | D2: =目次!D2 -> 第３章 機能設計 | T2: 作成日 | V2: 42398
A3: =目次!A3 -> 機能名 | T3: 作成者 | V3: 協和エクシオ
A4: =目次!A4 -> ３．１．４ 被災状況登録 | T4: 更新日
T5: 更新者
A6: 画面名 | D6: =目次!D18 -> ３．１．４．６ 被災状況追加報告 | O6: ＩＤ
B8: 【1】イベント 1/2
B10: № | C10: 項目名 | I10: トリガー
C11: 処理内容
B12: 1 | C12: ― | I12: 初期表示
C13: ＜1.1 前提条件＞
D14: 1.1.1 | E14: 被災状況詳細画面より遷移する。
C16: ＜1.2 初期処理＞
D17: 1.2.1 | E17: 画面入力項目を初期化する。
D18: 1.2.2 | E18: メッセージエリアを初期化する。
D19: 1.2.3 | E19: ヘッダーバーを初期化する。
F20: ・ ログイン中ユーザのユーザ名と組織名１をDBから取得する。
F21: ・ ユーザ名をヘッダー文言①に、組織名１をヘッダー文言②に表示する。
D22: 1.2.4 | E22: 前画面にて指定された災害ID／グループコード／会社コード／組織コード／ビルコード報告回数から、
E23: 被災状況情報を抽出する。
D24: 1.2.5 | E24: DBに登録された未削除の災害情報から、災害IDに紐づく、災害情報を抽出する。
D25: 1.2.6 | E25: DBに登録された未削除のビルデータ情報から、
E26: グループコード／会社コード／組織コード／ビルコードに紐づく、ビルデータ情報を抽出する。
D27: 1.2.7 | E27: 抽出したビルデータ情報のビル名を、ヘッダー文言③に表示する。
D28: 1.2.8 | E28: 抽出した災害情報／ビルデータ情報／被災状況情報を、
E29: 被災状況追加報告エリアに初期表示する。
D30: 1.2.9 | E30: 今回の報告回数を前回＋１回として表示する。
D31: 1.2.10 | E31: 報告日時欄に（システム日付 + 00時00分）をセットする。
B33: 2 | C33: クリアボタン | I33: 押下時
C34: ＜2.1 前提条件＞
D35: 2.1.1 | E35: クリアボタンを押下する。
C37: ＜2.2 クリア処理＞
D38: 2.2.1 | E38: 確認ダイアログを表示する。（NA0001)
E39: 「入力情報をクリアします。よろしいですか？」OK・キャンセル
F40: OK押下： 次の処理（2.2.2）へ進む。
F41: キャンセル押下： 処理を抜ける。
D42: 2.2.2 | E42: すべての入力（ラジオボタン含む）項目を初期表示時の状態に戻す。
D43: 2.2.3 | E43: メッセージエリアを初期化する。
B45: 3 | C45: 登録ボタン | I45: 押下時
C46: ＜3.1 前提条件＞
...

Sheet 被災状況CSV登録
A1: システム名 | D1: =目次!D1 -> 備蓄品管理システム | T1: Ｖｅｒ. | V1: 1.0
A2: =目次!A2 -> 章番号 | D2: =目次!D2 -> 第３章 機能設計 | T2: 作成日 | V2: 42398
A3: =目次!A3 -> 機能名 | T3: 作成者 | V3: 協和エクシオ
A4: =目次!A4 -> ３．１．４ 被災状況登録 | T4: 更新日
T5: 更新者
A6: 画面名 | D6: =目次!D20 -> ３．１．４．７ 被災状況CSV登録 | O6: ＩＤ
B8: 【1】イベント 1/5
B10: № | C10: 項目名 | I10: トリガー
C11: 処理内容
B12: 1 | C12: ― | I12: 初期表示
C13: ＜1.1 前提条件＞
D14: 1.1.1 | E14: 被災状況一覧画面より遷移する。
C16: ＜1.2 初期処理＞
D17: 1.2.1 | E17: CSVファイル欄の項目を初期化する。
D18: 1.2.2 | E18: メッセージエリアを初期化する。
D19: 1.2.3 | E19: ヘッダーバーを初期化する。
F20: ・ ログイン中ユーザのユーザ名と組織名１をDBから取得する。
F21: ・ ユーザ名をヘッダー文言①に、組織名１をヘッダー文言②に表示する。
D22: 1.2.4 | E22: 災害名プルダウンを、DBに登録された未削除の災害情報から生成する。
F23: ・ 災害発生日時／災害IDの降順でソートする。
F24: ・ 初期値として、被災状況一覧画面で表示中の災害名を表示する。
D25: 1.2.5 | E25: グループ名プルダウンの生成方法を「2.3.2 共通権限」の2.2を参照する。
D26: 1.2.6 | E26: 会社名プルダウンの生成方法を「2.3.2 共通権限」の2.2を参照する。
B28: 2 | C28: クリアボタン | I28: 押下時
C29: ＜2.1 前提条件＞
D30: 2.1.1 | E30: クリアボタンを押下する。
C32: ＜2.2 クリア処理＞
D33: 2.2.1 | E33: 確認ダイアログを表示する。（NA0001）
E34: 「入力情報をクリアします。よろしいですか？」OK・キャンセル
F35: OK押下： 次の処理（2.2.2）へ進む。
F36: キャンセル押下： 処理を抜ける。
D37: 2.2.2 | E37: すべての入力項目を初期表示時の状態に戻す。
D38: 2.2.3 | E38: メッセージエリアを初期化する。
B47: 【1】イベント 2/5
B49: № | C49: 項目名 | I49: トリガー
C50: 処理内容
B51: 3 | C51: 参照ボタン | I51: クリック時
C52: ＜3.1 前提条件＞
D53: 3.1.1 | E53: 参照ボタンを押下する。
C55: ＜3.2 ファイル参照処理＞
...
