Workbook

Sheet 目次
A1: システム名 | D1: 備蓄品管理システム | T1: Ｖｅｒ. | V1: 1.0 | AA1: 章 | AC1: 節 | AE1: 項
A2: 章番号 | D2: ="第"&DBCS($AA$3)&"章 "&AB3 -> 第３章 機能設計 | T2: 作成日 | V2: 2016/1/29 | AA2: 番 | AB2: 章分類 | AC2: 番 | AD2: 節分類 | AE2: 番 | AF2: 機能名
A3: 機能名 | T3: 作成者 | V3: 協和エクシオ | AA3: 3 | AB3: 機能設計 | AC3: 1 | AD3: 機能詳細 | AE3: 10 | AF3: 災害一覧
A4: =IF($AA$3="","",DBCS($AA$3))&IF($AC$3="","",DBCS("."&$AC$3))&IF($AE$3="","",DBCS("."&$AE$3))&DBCS(" ")&$AF$3 -> ３．１．１０ 災害一覧 | T4: 更新日
T5: 更新者
AA6: 段
AA7: 番 | AB7: 処理名
D8: =IF($AA8="","",IF($AA$3="","",DBCS($AA$3))&IF($AC$3="","",DBCS("."&$AC$3))&IF($AE$3="","",DBCS("."&$AE$3))&IF($AA8="","",DBCS("."&$AA8))&DBCS(" ")&$AB8) -> ３．１．１０．１ 災害一覧 | AA8: 1 | AB8: 災害一覧
D10: =IF($AA10="","",IF($AA$3="","",DBCS($AA$3))&IF($AC$3="","",DBCS("."&$AC$3))&IF($AE$3="","",DBCS("."&$AE$3))&IF($AA10="","",DBCS("."&$AA10))&DBCS(" ")&$AB10) -> ３．１．１０．２ 災害登録 | AA10: 2 | AB10: 災害登録
D12: =IF($AA12="","",IF($AA$3="","",DBCS($AA$3))&IF($AC$3="","",DBCS("."&$AC$3))&IF($AE$3="","",DBCS("."&$AE$3))&IF($AA12="","",DBCS("."&$AA12))&DBCS(" ")&$AB12) -> ３．１．１０．３ 災害詳細 | AA12: 3 | AB12: 災害詳細
D14: =IF($AA14="","",IF($AA$3="","",DBCS($AA$3))&IF($AC$3="","",DBCS("."&$AC$3))&IF($AE$3="","",DBCS("."&$AE$3))&IF($AA14="","",DBCS("."&$AA14))&DBCS(" ")&$AB14) -> ３．１．１０．４ 災害修正 | AA14: 4 | AB14: 災害修正
D16: =IF($AA16="","",IF($AA$3="","",DBCS($AA$3))&IF($AC$3="","",DBCS("."&$AC$3))&IF($AE$3="","",DBCS("."&$AE$3))&IF($AA16="","",DBCS("."&$AA16))&DBCS(" ")&$AB16)
D18: =IF($AA18="","",IF($AA$3="","",DBCS($AA$3))&IF($AC$3="","",DBCS("."&$AC$3))&IF($AE$3="","",DBCS("."&$AE$3))&IF($AA18="","",DBCS("."&$AA18))&DBCS(" ")&$AB18)
D20: =IF($AA20="","",IF($AA$3="","",DBCS($AA$3))&IF($AC$3="","",DBCS("."&$AC$3))&IF($AE$3="","",DBCS("."&$AE$3))&IF($AA20="","",DBCS("."&$AA20))&DBCS(" ")&$AB20)
D22: =IF($AA22="","",IF($AA$3="","",DBCS($AA$3))&IF($AC$3="","",DBCS("."&$AC$3))&IF($AE$3="","",DBCS("."&$AE$3))&IF($AA22="","",DBCS("."&$AA22))&DBCS(" ")&$AB22)
D24: =IF($AA24="","",IF($AA$3="","",DBCS($AA$3))&IF($AC$3="","",DBCS("."&$AC$3))&IF($AE$3="","",DBCS("."&$AE$3))&IF($AA24="","",DBCS("."&$AA24))&DBCS(" ")&$AB24)
D26: =IF($AA26="","",IF($AA$3="","",DBCS($AA$3))&IF($AC$3="","",DBCS("."&$AC$3))&IF($AE$3="","",DBCS("."&$AE$3))&IF($AA26="","",DBCS("."&$AA26))&DBCS(" ")&$AB26)
D28: =IF($AA28="","",IF($AA$3="","",DBCS($AA$3))&IF($AC$3="","",DBCS("."&$AC$3))&IF($AE$3="","",DBCS("."&$AE$3))&IF($AA28="","",DBCS("."&$AA28))&DBCS(" ")&$AB28)
D30: =IF($AA30="","",IF($AA$3="","",DBCS($AA$3))&IF($AC$3="","",DBCS("."&$AC$3))&IF($AE$3="","",DBCS("."&$AE$3))&IF($AA30="","",DBCS("."&$AA30))&DBCS(" ")&$AB30)
D32: =IF($AA32="","",IF($AA$3="","",DBCS($AA$3))&IF($AC$3="","",DBCS("."&$AC$3))&IF($AE$3="","",DBCS("."&$AE$3))&IF($AA32="","",DBCS("."&$AA32))&DBCS(" ")&$AB32)
D34: =IF($AA34="","",IF($AA$3="","",DBCS($AA$3))&IF($AC$3="","",DBCS("."&$AC$3))&IF($AE$3="","",DBCS("."&$AE$3))&IF($AA34="","",DBCS("."&$AA34))&DBCS(" ")&$AB34)

Sheet 災害一覧
A1: システム名 | D1: =目次!D1 -> 備蓄品管理システム | T1: Ｖｅｒ. | V1: 1.0
A2: =目次!A2 -> 章番号 | D2: =目次!D2 -> 第３章 機能設計 | T2: 作成日 | V2: 42398
A3: =目次!A3 -> 機能名 | T3: 作成者 | V3: 協和エクシオ
A4: =目次!A4 -> ３．１．１０ 災害一覧 | T4: 更新日
T5: 更新者
A6: 画面名 | D6: =目次!D8 -> ３．１．１０．１ 災害一覧 | O6: ＩＤ
B8: 【1】イベント 1/3
B10: № | C10: 項目名 | I10: トリガー
C11: 処理内容
B12: 1 | C12: ― | I12: 初期表示
C13: ＜1.1 前提条件＞
D14: 1.1.1 | E14: 地図画面より遷移する。
D15: 1.1.2 | E15: 災害登録画面より遷移する。
D16: 1.1.3 | E16: 災害詳細画面より遷移する。
D17: 1.1.4 | E17: 各画面のメニューバーから遷移する。
C19: ＜1.2 初期処理＞
D20: 1.2.1 | E20: 画面入力項目を初期化する。
D21: 1.2.2 | E21: メッセージエリアを初期化する。
D22: 1.2.3 | E22: ヘッダーバーを初期化する。
F23: ・ ログイン中ユーザのユーザ名と組織名１をDBから取得する。
F24: ・ ユーザ名をヘッダー文言①に、組織名１をヘッダー文言②に表示する。
D25: 1.2.4 | E25: 検索エリアの初期値の条件で、未削除の災害一覧を全て抽出する。
F26: ・ 検索項目が未入力の項目は、該当項目について全件検索とする。
F27: 検索項目 | J27: 検索条件
F28: 災害名 | J28: あいまい検索可能。
F29: 災害発生日時 | J29: 災害発生日時が指定期間内のデータを検索。
D30: 1.2.5 | E30: 抽出した災害一覧の件数を、ヘッダー文言③に表示する。
D31: 1.2.6 | E31: 抽出した災害一覧を、災害一覧エリアに表示する。
F32: ・ 以下のソート項目で並び替えした後に初期表示する。
F33: ソート項目 | L33: ソート順
F34: 災害ＩＤ | L34: 降順
F35: ・ 結果がゼロ件の場合、下記項目を非活性にする。
G36: ・ ページ遷移リンク
D37: 1.2.7 | E37: ページ遷移リンクの設定。
F38: ・ 次ページがある場合は、次ページリンクを設定する。
F39: ・ 前ページのリンクは、テキストの表示のみとする。
B41: 2 | C41: 検索ボタン | I41: 押下時
C42: ＜2.1 前提条件＞
D43: 2.1.1 | E43: 検索ボタンを押下する。
C45: ＜2.2 一覧検索処理＞
...

Sheet 災害登録
A1: システム名 | D1: =目次!D1 -> 備蓄品管理システム | T1: Ｖｅｒ. | V1: 1.0
A2: =目次!A2 -> 章番号 | D2: =目次!D2 -> 第３章 機能設計 | T2: 作成日 | V2: 42398
A3: =目次!A3 -> 機能名 | T3: 作成者 | V3: 協和エクシオ
A4: =目次!A4 -> ３．１．１０ 災害一覧 | T4: 更新日
T5: 更新者
A6: 画面名 | D6: =目次!D10 -> ３．１．１０．２ 災害登録 | O6: ＩＤ
B8: 【1】イベント 1/2
B10: № | C10: 項目名 | I10: トリガー
C11: 処理内容
B12: 1 | C12: ― | I12: 初期表示
C13: ＜1.1 前提条件＞
D14: 1.1.1 | E14: 災害一覧画面より遷移する。
C16: ＜1.2 初期処理＞
D17: 1.2.1 | E17: 画面入力項目を初期化する。
D18: 1.2.2 | E18: メッセージエリアを初期化する。
D19: 1.2.3 | E19: ヘッダーバーを初期化する。
F20: ・ ログイン中ユーザのユーザ名と組織名１をDBから取得する。
F21: ・ ユーザ名をヘッダー文言①に、組織名１をヘッダー文言②に表示する。
D22: 1.2.4 | E22: 災害発生日時欄に（システム日付 + 00時00分）をセットする。
B24: 2 | C24: クリアボタン | I24: 押下時
C25: ＜2.1 前提条件＞
D26: 2.1.1 | E26: クリアボタンを押下する。
C28: ＜2.2 クリア処理＞
D29: 2.2.1 | E29: 確認ダイアログを表示する。（NA0001）
E30: 「入力情報をクリアします。よろしいですか？」OK・キャンセル
F31: OK押下：次の処理（2.2.2）へ進む。
F32: キャンセル押下：処理を抜ける。
D33: 2.2.2 | E33: すべての入力項目を、初期表示時の状態に戻す。
D34: 2.2.3 | E34: メッセージエリアを初期化する。
B36: 3 | C36: 登録ボタン | I36: 押下時
C37: ＜3.1 前提条件＞
D38: 3.1.1 | E38: 登録ボタンを押下する。
C40: ＜3.2 登録確定処理＞
D41: 3.2.1 | E41: 確認ダイアログを表示する。（NI0001）
F42: 「災害情報を登録します。よろしいですか？」OK・キャンセル
G43: OK押下： 次の処理（3.2.2）へ進む。
G44: キャンセル押下： 処理を抜ける。
D45: 3.2.2 | E45: 必須入力チェック
F46: ・ チェック内容は、【２】の必須入力チェックを参照。
D47: 3.2.3 | E47: 属性チェック
...

Sheet 災害詳細
A1: システム名 | D1: =目次!D1 -> 備蓄品管理システム | T1: Ｖｅｒ. | V1: 1.0
A2: =目次!A2 -> 章番号 | D2: =目次!D2 -> 第３章 機能設計 | T2: 作成日 | V2: 42398
A3: =目次!A3 -> 機能名 | T3: 作成者 | V3: 協和エクシオ
A4: =目次!A4 -> ３．１．１０ 災害一覧 | T4: 更新日
T5: 更新者
A6: 画面名 | D6: =目次!D12 -> ３．１．１０．３ 災害詳細 | O6: ＩＤ
B8: 【1】イベント 1/2
B10: № | C10: 項目名 | I10: トリガー
C11: 処理内容
B12: 1 | C12: ― | I12: 初期表示
C13: ＜1.1 前提条件＞
D14: 1.1.1 | E14: 災害一覧画面より遷移する。
D15: 1.1.2 | E15: 災害登録画面より遷移する。
D16: 1.1.3 | E16: 災害修正画面より遷移する。
C18: ＜1.2 初期処理＞
D19: 1.2.1 | E19: ヘッダーバーを初期化する。
F20: ・ ログイン中ユーザのユーザ名と組織名１をDBから取得する。
F21: ・ ユーザ名をヘッダー文言①に、組織名１をヘッダー文言②に表示する。
D22: 1.2.2 | E22: 前画面にて指定された災害ＩＤから、災害情報を抽出する。
D23: 1.2.3 | E23: 抽出した災害一覧の災害IDを、ヘッダー文言③に表示する。
D24: 1.2.4 | E24: 抽出した災害情報を、災害詳細エリアに表示する。
B26: 2 | C26: 修正ボタン | I26: 押下時
C27: ＜2.1 前提条件＞
D28: 2.1.1 | E28: 修正ボタンを押下する。
C30: ＜2.2 画面遷移処理＞
D31: 2.2.1 | E31: 指定した災害情報の災害修正画面へ遷移する。
B33: 3 | C33: 削除ボタン | I33: 押下時
C34: ＜3.1 前提条件＞
D35: 3.1.1 | E35: 削除ボタンを押下する。
C37: ＜3.2 削除確定処理＞
D38: 3.2.1 | E38: 確認ダイアログを表示する。（NI0003）
F39: 「災害情報を削除します。よろしいですか？」OK・キャンセル
G40: OK押下： 次の処理（3.2.2）へ進む。
G41: キャンセル押下： 処理を抜ける。
D42: 3.2.2 | E42: 被災状況情報有無チェック
F43: ・ チェック内容は、【２】の被災状況情報有無チェックを参照。
D44: 3.2.3 | E44: フリーワード情報有無チェック
F45: ・ チェック内容は、【２】のフリーワード情報有無チェックを参照。
D46: 3.2.4 | E46: 排他チェック
F47: ・ チェック内容は、【２】の排他チェックを参照。
...

Sheet 災害修正
A1: システム名 | D1: =目次!D1 -> 備蓄品管理システム | T1: Ｖｅｒ. | V1: 1.0
A2: =目次!A2 -> 章番号 | D2: =目次!D2 -> 第３章 機能設計 | T2: 作成日 | V2: 42398
A3: =目次!A3 -> 機能名 | T3: 作成者 | V3: 協和エクシオ
A4: =目次!A4 -> ３．１．１０ 災害一覧 | T4: 更新日
T5: 更新者
A6: 画面名 | D6: =目次!D14 -> ３．１．１０．４ 災害修正 | O6: ＩＤ
B8: 【1】イベント 1/2
B10: № | C10: 項目名 | I10: トリガー
C11: 処理内容
B12: 1 | C12: ― | I12: 初期表示
C13: ＜1.1 前提条件＞
D14: 1.1.1 | E14: 災害詳細画面より遷移する。
C16: ＜1.2 初期処理＞
D17: 1.2.1 | E17: 画面入力項目を初期化する。
D18: 1.2.2 | E18: メッセージエリアを初期化する。
D19: 1.2.3 | E19: ヘッダーバーを初期化する。
F20: ・ ログイン中ユーザのユーザ名と組織名１をDBから取得する。
F21: ・ ユーザ名をヘッダー文言①に、組織名１をヘッダー文言②に表示する。
D22: 1.2.4 | E22: 前画面にて指定された災害ＩＤから、災害情報を抽出する。
D23: 1.2.5 | E23: 抽出した災害情報の災害IDを、ヘッダー文言③に表示する。
D24: 1.2.6 | E24: 抽出した災害情報を、災害修正エリアに表示する。
B26: 2 | C26: クリアボタン | I26: 押下時
C27: ＜2.1 前提条件＞
D28: 2.1.1 | E28: クリアボタンを押下する。
C30: ＜2.2 クリア処理＞
D31: 2.2.1 | E31: 確認ダイアログを表示する。（NA0001）
E32: 「入力情報をクリアします。よろしいですか？」OK・キャンセル
F33: OK押下：次の処理（2.2.2）へ進む。
F34: キャンセル押下：処理を抜ける。
D35: 2.2.2 | E35: すべての入力項目を、初期表示時の状態に戻す。
D36: 2.2.3 | E36: メッセージエリアを初期化する。
B38: 3 | C38: 登録ボタン | I38: 押下時
C39: ＜3.1 前提条件＞
D40: 3.1.1 | E40: 登録ボタンを押下する。
C42: ＜3 登録確定処理＞
D43: 3.2.1 | E43: 修正確認ダイアログを表示する。（NI0002）
F44: 「災害情報を修正します。よろしいですか？」OK・キャンセル
G45: OK押下： 次の処理（3.2.2）へ進む。
G46: キャンセル押下： 処理を抜ける。
D47: 3.2.2 | E47: 必須入力チェック
...
